<?xml version="1.0" encoding="utf-8"?>
<mujoco model="antrobot">
	<compiler/>
	<option gravity="0 0 0"/>
	<size nconmax="500" njmax="1000"/>
	<custom/>
	<default/>
	<asset>
		<texture builtin="gradient" height="100" rgb1="1 1 1" rgb2="0 0 0" type="skybox" width="100"/>
		<texture builtin="flat" height="1278" mark="cross" markrgb="1 1 1" name="texgeom" random="0.01" rgb1="0.8 0.6 0.4" rgb2="0.8 0.6 0.4" type="cube" width="127"/>
		<texture builtin="checker" height="100" name="texplane" rgb1="0 0 0" rgb2="0.8 0.8 0.8" type="2d" width="100"/>
		<material name="MatPlane" reflectance="0.5" shininess="1" specular="1" texrepeat="60 60" texture="texplane"/>
		<material name="geom" texture="texgeom" texuniform="true"/>
	</asset>
	<worldbody>
		<light cutoff="100" diffuse="1 1 1" dir="0 0 -1.3" directional="true" exponent="1" pos="0 0 1.3" specular="0.1 0.1 0.1"/>
		<geom conaffinity="1" condim="3" material="MatPlane" name="floor" pos="0 0 0" rgba="0.8 0.9 0.8 1" size="40 40 40" type="plane"/>
		<body name="root" pos="0 0 2" euler="0 0 0">
			<geom name="geomroot" pos="0 0 0" size="0.25" type="sphere"/>
			<body name="part1" pos="0.25 0 0" euler="0 0 0">
				<geom fromto="0 0 0 0.5 0 0" name="geompart1" size="0.1" type="capsule"/>
				<body name="part2" pos="0.5 0 0" euler="0 90 0">
					<geom fromto="0 0 0 0.4 0 0" name="geompart2" size="0.1" type="capsule"/>
					<joint axis="0 1 0" name="joint_joint11" pos="0 0 0" range="-45 45" type="hinge"/>
				</body>
			</body>
			<body name="part3" pos="0 0.25 0" euler="0 0 90">
				<geom fromto="0 0 0 0.5 0 0" name="geompart3" size="0.1" type="capsule"/>
				<body name="part4" pos="0.5 0 0" euler="0 90 0">
					<geom fromto="0 0 0 0.4 0 0" name="geompart4" size="0.1" type="capsule"/>
					<joint axis="0 1 0" name="joint_joint31" pos="0 0 0" range="-45 45" type="hinge"/>
				</body>
			</body>
		</body>
	</worldbody>
	<actuator>
		<motor ctrllimited="true" ctrlrange="-1 1" joint="joint_joint11"/>
		<motor ctrllimited="true" ctrlrange="-1 1" joint="joint_joint31"/>
	</actuator>
</mujoco>